Workbook
Name SegmentaciónDeDatos_AñoMes: #N/A
Name SegmentaciónDeDatos_Categoría1: #N/A
Name TBL_REND_TARGET: REND_TARGET[]

Sheet DQO
B2: DIA | C2: TURNO | D2: HORA | E2: OPERARIO | F2: SALIDA DAF DQO <1000 (mg O2/l) | G2: DAF pH PORTATIL (5,5 - 9,5) (upH) | H2: SALIDA DAF Tª 40 (ºC) | I2: SALIDA DAF CE FIJA <5000 (µS/cm) | K2: DIA_INC | L2: TIPO | M2: PARÁMETRO | N2: VALOR_MUESTRA | O2: VALOR_REFERENCIA | P2: GRAVEDAD_EXP | Q2: COSTE | R2: VENCIMIENTO
B3: 45659 | C3: mañana | D3: 0.32638889 | E3: elena | F3: 53 | G3: 7.44 | I3: 0.95 | K3: 45659 | L3: Desviación | M3: Nitrógeno | N3: 70 | O3: 40 | P3: Grave y Recurrente | Q3: 100 | R3: 46082
B4: 45660 | C4: mañana | D4: 0.33333333 | E4: elena | F4: 43 | G4: 7.56 | I4: 0.94
B5: 45664 | C5: mañana | D5: 0.35416667 | E5: elena | F5: 29 | G5: 7.77 | I5: 0.77
B6: 45665 | C6: mañana | D6: 0.47916667 | E6: elena | F6: 33 | G6: 7.84 | I6: 0.85
B7: 45666 | C7: mañana | D7: 0.55208333 | E7: elena | F7: 56 | G7: 7.39 | I7: 0.7
B8: 45667 | C8: mañana | D8: 0.56944444 | E8: elena | F8: 40 | G8: 7.8 | I8: 1.18
B9: 45673 | C9: mañana | D9: 0.41666667 | E9: elena | F9: 90 | G9: 7.5 | I9: 0.89
B10: 45674 | C10: mañana | D10: 0.375 | E10: elena | F10: 140 | G10: 7.62 | I10: 0.94
B11: 45677 | C11: mañana | D11: 0.51041667 | E11: elena | F11: 94 | G11: 7.5 | I11: 0.91
B12: 45678 | C12: mañana | D12: 0.47916667 | E12: elena | F12: 174 | G12: 7.3 | I12: 0.98
B13: 45679 | C13: mañana | D13: 0.4375 | E13: elena | F13: 126 | G13: 7.47 | I13: 1.22
B14: 45681 | C14: mañana | D14: 0.65972222 | E14: elena | F14: 150 | G14: 7.85 | I14: 1.16
B15: 45692 | C15: mañana | D15: 0.39583333 | E15: elena | F15: 84 | G15: 7.64 | I15: 0.85
... B39: 45754 | C39: mañana | D39: 0.36111111 | E39: DIANA | F39: 13 | G39: 8 | I39: 0.92
B40: =+B39+1 -> 45755 | C40: mañana | D40: 0.33333333 | E40: LAYNER | F40: 123 | G40: 7.67 | I40: 1.04
B41: =+B40+1 -> 45756 | C41: mañana | D41: 0.36805556 | E41: DIANA | F41: 40 | G41: 7.71 | I41: 0.98
B42: =+B41+1 -> 45757 | C42: mañana | D42: 0.58333333 | E42: LAYNER | F42: 34 | G42: 7.83 | I42: 0.95
B43: =+B42+1 -> 45758 | C43: mañana | D43: 0.55555556 | E43: DIANA | F43: 45 | G43: 7.15 | I43: 1.34
B44: =+B43+3 -> 45761 | C44: mañana | D44: 0.30208333 | E44: TAMARA | F44: 44 | G44: 7.6 | I44: 1.21
B45: =+B44+1 -> 45762 | C45: mañana | D45: 0.27083333 | E45: TAMARA | F45: 183 | G45: 7.53 | I45: 1.34
B46: =+B45+1 -> 45763 | C46: mañana | D46: 0.29166667 | E46: TAMARA | F46: 171 | G46: 7.56 | I46: 1.21
B47: 45768 | C47: MAÑANA | D47: 0.36111111 | E47: LAYNER | F47: 115 | G47: 7.53 | I47: 0.9
B48: 45769 | C48: MAÑANA | D48: 0.35069444 | E48: LAYNER | F48: 256 | G48: 7.72 | I48: 0.99
B49: 45771 | C49: MAÑANA | D49: 0.47222222 | E49: DIANA | F49: 264 | G49: 7.32 | I49: 0.91
B50: 45772 | C50: MAÑANA | D50: 0.4375 | E50: LAYNER | F50: 179 | G50: 7.44 | I50: 0.91
B51: 45775 | C51: MAÑANA | D51: 0.35416667 | E51: DIANA | F51: 119 | G51: 7.73 | I51: 0.87
B52: 45776 | C52: MAÑANA | D52: 0.41666667 | E52: TAMARA | F52: 358 | G52: 4.59 | I52: 1.04
B53: 45777 | C53: MAÑANA | D53: 0.33333333 | E53: DIANA | F53: 602 | G53: 7.47 | I53: 1.26
B54: 45778 | C54: MAÑANA | D54: 0.36111111 | E54: LAYNER | F54: 405 | G54: 7.62 | I54: 1.18
B55: 45779 | C55: MAÑANA | D55: 0.34375 | E55: TAMARA | F55: 245 | G55: 7.71 | I55: 1.1
B56: 45782 | C56: MAÑANA | D56: 0.44444444 | E56: DIANA Y LAYNER | F56: 367 | G56: 7.74 | I56: 1.13
B57: 45783 | C57: MAÑANA | D57: 0.50347222 | E57: DIANA Y LAYNER | F57: 636 | G57: 7.56 | I57: 1.07
B58: 45784 | C58: MAÑANA | D58: 0.48958333 | E58: DIANA Y LAYNER | F58: 868 | G58: 7.01 | I58: 1.37
... B68: 45798 | C68: MAÑANA | D68: 0.53472222 | E68: DIANA Y LAYNER | F68: 248 | G68: 7.64 | I68: 1.05
B69: 45799 | C69: MAÑANA | E69: DIANA Y LAYNER | F69: 221 | G69: 7.52 | I69: 0.94
B70: 45800 | C70: MAÑANA | D70: 0.45833333 | E70: DIANA Y LAYNER | F70: 203 | G70: 7.4 | I70: 0.88
B71: 45803 | C71: MAÑANA | D71: 0.375 | E71: DIANA Y ABY | F71: 180 | G71: 7.87 | I71: 0.98
B72: 45804 | C72: MAÑANA | D72: 0.34722222 | E72: DIANA Y MARTA | F72: 350 | G72: 7.51 | I72: 1.06
B73: 45805 | C73: MAÑANA | D73: 0.43055556 | E73: DIANA Y MARTA | F73: 457 | G73: 7.16 | I73: 0.99
...

Sheet Base_Rendimientos
A1: =3045*0.42 -> 1278.9 | G1: =+E1+A1 -> 1278.9 | I1: =SUBTOTAL(9,I2:I323) -> 47855848 | J1: =SUBTOTAL(9,J2:J323) -> 47263334 | O1: =SUBTOTAL(9,O2:O323) -> 554214 | R1: =SUBTOTAL(9,R2:R323)/J1 -> 0.022494372 | S1: =SUBTOTAL(9,S2:S323) -> 14008.66 | T1: =SUBTOTAL(9,T2:T323)/I1 -> 0.88617174 | U1: =+T1 -> 0.88617174 | V1: =SUMPRODUCT(Tabla_master_rend[MG_suero],Tabla_master_rend[L_suero Total]) -> 62427.917 | W1: =SUMPRODUCT(Tabla_master_rend[MP_suero],Tabla_master_rend[L_suero Total]) -> 372620.09 | X1: =SUBTOTAL(9,X2:X323) -> 33659758 | Y1: =SUBTOTAL(9,Y2:Y323) -> 11266351 | Z1: =+X1/Y1 -> 2.9876362 | AA1: =SUBTOTAL(9,AA2:AA323) -> 8748741.8 | AD1: =SUBTOTAL(9,AD2:AD323) -> 850930 | AE1: =SUBTOTAL(9,AE2:AE323) -> 0 | AH1: =+G1/15224 -> 0.084005518 | AI1: =SUBTOTAL(9,AI2:AI323) -> 5384399.1 | AJ1: =+I1/AI1 -> 8.8878717 | AK1: =+I1/(AI1-BR1) -> 9.1812137 | AM1: =SUBTOTAL(9,AM2:AM323) -> 3535676 | AR1: =SUBTOTAL(9,AR2:AR323) -> 425263.6 | AU1: =SUBTOTAL(9,AU2:AU323) -> 3189477 | AV1: =SUBTOTAL(9,AV2:AV323) -> 9391.84 | AW1: =SUBTOTAL(9,AW2:AW323) -> 21347.1 | AX1: =SUBTOTAL(9,AX2:AX323) -> 8546.9 | AY1: =SUBTOTAL(9,AY2:AY323) -> 39285.84 | AZ1: =+(AV1+AW1+AX1)/(AI1) -> 0.0072962348 | BA1: =SUBTOTAL(9,BA2:BA323) -> 59701 | BB1: =+BA1/(BA1+BK1) -> 0.011169268 | BC1: =SUBTOTAL(9,BC2:BC323) -> 742777 | BD1: =SUBTOTAL(9,BD2:BD323) -> 722503 | BE1: =SUBTOTAL(9,BE2:BE323) -> 5225397 | BF1: =SUBTOTAL(9,BF2:BF323) -> 41843 | BG1: =SUBTOTAL(9,BG2:BG323) -> 44643.1 | BH1: =SUBTOTAL(9,BH2:BH323) -> 6265.6 | BI1: =SUBTOTAL(9,BI2:BI323) -> 51996.2 | BJ1: =SUBTOTAL(9,BJ2:BJ323) -> 20660 | ... BN1: =SUBTOTAL(9,BN2:BN323) -> 4779.06 | BO1: =+BM1/BK1 -> 0.012868915 | BP1: =+BO1*(1-BZ1) -> 0.0083733744 | BQ1: =+BR1/AI1 -> 0.031950241 | BR1: =SUBTOTAL(9,BR2:BR323) -> 172032.85 | BS1: =SUBTOTAL(9,BS2:BS323) -> 2713819.7 | BT1: =SUBTOTAL(9,BT2:BT591) -> -24776.58 | BU1: =+BT1/BK1 -> -0.0046877289 | BW1: Precio Nata | BX1: =SUBTOTAL(9,BX2:BX323) -> 264394.74 | BY1: =SUBTOTAL(9,BY2:BY323) -> 92361.889 | BZ1: =+BY1/BX1 -> 0.34933331 | CA1: 0.0065 | CB1: 0.01 | CC1: 0.0105 | CD1: =SUBTOTAL(9,CD2:CD323) -> 109814.82 | CE1: =+CD1/AI1 -> 0.020395 | CF1: =+BR1/AI1 -> 0.031950241 | CG1: =SUBTOTAL(9,CG2:CG323) -> -62218.032 | CI1: =SUBTOTAL(9,CI2:CI323) -> -80883.441
A2: Fecha | B2: mes | C2: Mes_Nom | D2: Día | E2: Lote | F2: Tipo_Leche | G2: Producto | H2: Cubas_prod | I2: Litros_Leche_Total | J2: L_Leche_ent | K2: %MG_Leche | L2: %MP_Leche | M2: EST_% | N2: Desn_en_linea | O2: L_desn_ext | P2: L_cabra | Q2: L_oveja | R2: Litros_Nata | S2: L_nata_suero | T2: L_suero Total | U2: %Suero_vs_leche | V2: MG_suero | W2: MP_suero | X2: L_suero para con | Y2: L_suero_con | Z2: Rartio_sueroC | AA2: L_Suero_Sobrante | AB2: MG_sueroc | AC2: MP_sueroc | AD2: L_LPS_Gen | AE2: L_LPS_incor | AF2: gr_LPS | AG2: MG_LPS | AH2: MP_LPS | AI2: Kg_Queso_Blan | AJ2: RDTO_Blanco | AK2: RDTO_NETO | AL2: REND_TARGET | AM2: Kg_Solidos_leche | AN2: %MG_QUESO | AO2: %PT_QUESO | AP2: ES_QUESO | AQ2: Rendimiento_Solidos_% | AR2: Kg_MG_Nata | AS2: %RECUP_MG | AT2: %RECUP_PT | AU2: Valor_Nata_€ | AV2: Kg_Finos | AW2: Kg_Llenadora | AX2: Kg_Desmoldeo | AY2: Merma_fab | AZ2: % Merma_fab2 | BA2: L_Agua | BB2: % oreo | BC2: B_totales | BD2: B_OK_uni | BE2: B_OK_kg | BF2: B_altas | BG2: B_bajas | BH2: B_rotas | BI2: B_feas | BJ2: B_lab | BK2: Kg_SalidaSecadero | BL2: Kg_rebaba | BM2: Kg_mer_env_real | BN2: kg_mer_lab_real | BO2: %Merma_env | BP2: %Merma_env_corr | BQ2: % merma TOT | BR2: Merma_TOT | BS2: Kg_Env_Total | BT2: Diferencia_Env_vs_Sec_kg | BU2: Diferencia_Env_vs_Sec_% | BV2: Coste_Leche_€ | BW2: €/kg_MPQueso | BX2: Merma_inic | BY2: Recup_kg | BZ2: Recup_% | CA2: Merma_ppto fab | CB2: Merma_ppto oreo | CC2: Merma_ppto Env/Enc | CD2: Merma_T ppto | CE2: Merma_T ppto % | CF2: Merma_T real % | CG2: DIF R Vs PPTO | CH2: IMPACTO | CI2: IMPACTO_vs_PPTO | CK2: DATO MEDIA ENE | CM2: 1.3 | CO2: Precio Nata
A3: 45659 | B3: 1 | C3: =+UPPER(TEXT(Tabla_master_rend[[#This Row],[Fecha]],"MMM")) -> ENE | D3: =+UPPER(TEXT(Tabla_master_rend[[#This Row],[Fecha]],"ddd")) -> JU | E3: 020125726 | F3: VACA | G3: GOUDA_LIGHT | H3: 2 | I3: =+Tabla_master_rend[[#This Row],[L_Leche_ent]]+Tabla_master_rend[[#This Row],[L_desn_ext]]+Tabla_master_rend[[#This Row],[L_cabra]]+Tabla_master_rend[[#This Row],[L_oveja]] -> 31269 | J3: 31269 | K3: 0.0424 | L3: 0.0351 | M3: =0.93*K3+0.74*L3+0.048 -> 0.113406 | N3: NO | O3: 0 | P3: 0 | Q3: 0 | R3: 1953.3 | T3: 27600 | U3: =+Tabla_master_rend[[#This Row],[L_suero Total]]/Tabla_master_rend[[#This Row],[Litros_Leche_Total]] -> 0.88266334 | V3: 0.0023 | W3: 0.0099 | X3: =112998/(211440+27600)*27600 -> 13046.958 | Y3: =(8475+25405)/(211440+27600)*27600 -> 3911.8474 | Z3: =IF(Tabla_master_rend[[#This Row],[L_suero para con]]=0,0,+Tabla_master_rend[[#This Row],[L_suero para con]]/Tabla_master_rend[[#This Row],[L_suero_con]]) -> 3.335242 | AA3: =+Tabla_master_rend[[#This Row],[L_suero Total]]-Tabla_master_rend[[#This Row],[L_suero para con]] -> 14553.042 | AD3: 0 | AE3: 0 | AF3: 0 | AG3: 0 | AH3: 0 | AI3: =+Tabla_master_rend[[#This Row],[Kg_Finos]]+Tabla_master_rend[[#This Row],[Kg_Llenadora]]+Tabla_master_rend[[#This Row],[Kg_Desmoldeo]]+Tabla_master_rend[[#This Row],[L_Agua]]+Tabla_master_rend[[#This Row],[Kg_SalidaSecadero]] -> 2909.7116 | AJ3: =+Tabla_master_rend[[#This Row],[Litros_Leche_Total]]/Tabla_master_rend[[#This Row],[Kg_Queso_Blan]] -> 10.746426 | AK3: =+Tabla_master_rend[[#This Row],[Litros_Leche_Total]]/(Tabla_master_rend[[#This Row],[Kg_Queso_Blan]]-Tabla_master_rend[[#This Row],[Merma_TOT]]) -> 11.53744 | AL3: =VLOOKUP(G3,REND_TARGET[#All],8,FALSE) -> #N/A | AM3: =(I3*1.03*Tabla_master_rend[[#This Row],[%MG_Leche]])+(I3*1.03*Tabla_master_rend[[#This Row],[%MP_Leche]]) -> 2496.0479 | AN3: 0.1792 | AO3: 0.2809 | AP3: 0.5123 | AQ3: =+Tabla_master_rend[[#This Row],[Kg_Queso_Blan]]*Tabla_master_rend[[#This Row],[ES_QUESO]]/(Tabla_master_rend[[#This Row],[Kg_Solidos_leche]]) -> 0.59720217 | AR3: =R3*0.4 -> 781.32 | AS3: =+(Tabla_master_rend[[#This Row],[Kg_Queso_Blan]]*Tabla_master_rend[[#This Row],[%MG_QUESO]]+(Tabla_master_rend[[#This Row],[Kg_MG_Nata]]))/(Tabla_master_rend[[#This Row],[Litros_Leche_Total]]*1.03*Tabla_master_rend[[#This Row],[%MG_Leche]]) -> 0.95398332 | AT3: =+Tabla_master_rend[[#This Row],[Kg_Queso_Blan]]*Tabla_master_rend[[#This Row],[%PT_QUESO]]/(Tabla_master_rend[[#This Row],[Litros_Leche_Total]]*1.03*Tabla_master_rend[[#This Row],[%MP_Leche]]) -> 0.72300841 | AU3: =AR3*$CO$3 -> 5859.9 | AV3: 7.1115939 | AW3: 9.3 | AX3: 20.3 | AY3: =SUM(Tabla_master_rend[[#This Row],[Kg_Finos]:[Kg_Desmoldeo]]) -> 36.711594 | AZ3: =+(Tabla_master_rend[[#This Row],[Kg_Finos]]+Tabla_master_rend[[#This Row],[Kg_Llenadora]]+Tabla_master_rend[[#This Row],[Kg_Desmoldeo]])/(Tabla_master_rend[[#This Row],[Kg_Queso_Blan]]) -> 0.012616918 | BA3: 30 | BB3: =+Tabla_master_rend[[#This Row],[L_Agua]]/(Tabla_master_rend[[#This Row],[L_Agua]]+Tabla_master_rend[[#This Row],[Kg_SalidaSecadero]]) -> 0.010442047 | BC3: 423 | BD3: 385 | BE3: 2650 | BF3: 0 | BG3: 0 | BH3: =11*5.8 -> 63.8 | BI3: =22*5.8 -> 127.6 | BJ3: 30 | BK3: 2843 | BL3: 1.16 | BM3: 127.41 | BN3: 4.21 | BO3: =+SUM(Tabla_master_rend[[#This Row],[B_altas]:[B_lab]])/Tabla_master_rend[[#This Row],[Kg_SalidaSecadero]] -> 0.077875484 | BP3: =+(Tabla_master_rend[[#This Row],[Kg_mer_env_real]]+Tabla_master_rend[[#This Row],[kg_mer_lab_real]])/Tabla_master_rend[[#This Row],[Kg_SalidaSecadero]] -> 0.046296166 | BQ3: =+Tabla_master_rend[[#This Row],[Merma_TOT]]/Tabla_master_rend[[#This Row],[Kg_Queso_Blan]] -> 0.068560607 | BR3: =+Tabla_master_rend[[#This Row],[kg_mer_lab_real]]+Tabla_master_rend[[#This Row],[Kg_mer_env_real]]+Tabla_master_rend[[#This Row],[Kg_rebaba]]+Tabla_master_rend[[#This Row],[L_Agua]]+Tabla_master_rend[[#This Row],[Kg_Desmoldeo]]+Tabla_master_rend[[#This Row],[Kg_Llenadora]]+Tabla_master_rend[[#This Row],[Kg_Finos]] -> 199.49159 | BT3: =IF(+Tabla_master_rend[[#This Row],[Kg_Env_Total]]=0,0,Tabla_master_rend[[#This Row],[Kg_Env_Total]]-Tabla_master_rend[[#This Row],[Kg_SalidaSecadero]]) -> 0 | BU3: =+Tabla_master_rend[[#This Row],[Diferencia_Env_vs_Sec_kg]]/Tabla_master_rend[[#This Row],[Kg_SalidaSecadero]] -> 0 | BV3: =IFERROR(Tabla_master_rend[[#This Row],[Litros_Leche_Total]]*SUMIFS(tbl_PrecioLeche[PMV_eur_L],tbl_PrecioLeche[AñoMes],TEXT(Tabla_master_rend[[#This Row],[Fecha]],"yyyy-mm"),tbl_PrecioLeche[Tipo_Leche],Tabla_master_rend[[#This Row],[Tipo_Leche]]),"") -> 0 | BW3: =+(Tabla_master_rend[[#This Row],[Coste_Leche_€]]-Tabla_master_rend[[#This Row],[Kg_MG_Nata]]*$CO$3)/Tabla_master_rend[[#This Row],[Kg_Queso_Blan]] -> -2.0139109 | BX3: =SUM(Tabla_master_rend[[#This Row],[Kg_Finos]:[Kg_Desmoldeo]])+Tabla_master_rend[[#This Row],[L_Agua]]+SUM(Tabla_master_rend[[#This Row],[B_altas]:[B_lab]]) -> 288.11159 | BY3: =+BX3-Tabla_master_rend[[#This Row],[Merma_TOT]] -> 88.62 | BZ3: =+BY3/BX3 -> 0.30758915 | CA3: =+Tabla_master_rend[[#This Row],[Kg_Queso_Blan]]*$CA$1 -> 18.913125 | CB3: =+Tabla_master_rend[[#This Row],[Kg_Queso_Blan]]*($CB$1-$CA$1) -> 10.183991 | CC3: =+(Tabla_master_rend[[#This Row],[Kg_Queso_Blan]]-CA3-CB3)*$CC$1 -> 30.246452 | CD3: =+CA3+CB3+CC3 -> 59.343568 | CE3: =+CD3/Tabla_master_rend[[#This Row],[Kg_Queso_Blan]] -> 0.020395 | CF3: =+Tabla_master_rend[[#This Row],[Merma_TOT]]/Tabla_master_rend[[#This Row],[Kg_Queso_Blan]] -> 0.068560607 | CG3: =CD3-Tabla_master_rend[[#This Row],[Merma_TOT]] -> -140.14803 | CH3: {=-BR3 * IFERROR(INDEX('Precio Leche_EBITDA_Ventas'!$BD$87:$BD$110,MATCH(1,('Precio Leche_EBITDA_Ventas'!$AZ$87:$AZ$110=YEAR(A3))*('Precio Leche_EBITDA_Ventas'!$BB$87:$BB$110=C3),0)),1.3)} -> -698.22058 | CI3: =+CG3*$CM$2 -> -182.19243 | CK3: Venta Kg Q Ok | CM3: 4.775 | CO3: 7.5
A4: 45659 | B4: 1 | C4: =+UPPER(TEXT(Tabla_master_rend[[#This Row],[Fecha]],"MMM")) -> ENE | D4: =+UPPER(TEXT(Tabla_master_rend[[#This Row],[Fecha]],"ddd")) -> JU | E4: 020125226 | F4: VACA | G4: GOUDA | H4: 15 | I4: =+Tabla_master_rend[[#This Row],[L_Leche_ent]]+Tabla_master_rend[[#This Row],[L_desn_ext]]+Tabla_master_rend[[#This Row],[L_cabra]]+Tabla_master_rend[[#This Row],[L_oveja]] -> 229311 | J4: 229311 | K4: 0.0402 | L4: 0.0339 | M4: =0.93*K4+0.74*L4+0.048 -> 0.110472 | N4: NO | O4: 0 | P4: 0 | Q4: 0 | R4: 3791.7 | T4: 211440 | U4: =+Tabla_master_rend[[#This Row],[L_suero Total]]/Tabla_master_rend[[#This Row],[Litros_Leche_Total]] -> 0.92206654 | V4: 0.0023 | W4: 0.0099 | X4: =112998/(211440+27600)*211440 -> 99951.042 | Y4: =(8475+25405)/(211440+27600)*211440 -> 29968.153 | Z4: =IF(Tabla_master_rend[[#This Row],[L_suero para con]]=0,0,+Tabla_master_rend[[#This Row],[L_suero para con]]/Tabla_master_rend[[#This Row],[L_suero_con]]) -> 3.335242 | AA4: =+Tabla_master_rend[[#This Row],[L_suero Total]]-Tabla_master_rend[[#This Row],[L_suero para con]] -> 111488.96 | AD4: 5516 | AE4: 0 | AF4: 0 | AG4: 0.0117 | AH4: 0.058 | AI4: =+Tabla_master_rend[[#This Row],[Kg_Finos]]+Tabla_master_rend[[#This Row],[Kg_Llenadora]]+Tabla_master_rend[[#This Row],[Kg_Desmoldeo]]+Tabla_master_rend[[#This Row],[L_Agua]]+Tabla_master_rend[[#This Row],[Kg_SalidaSecadero]] -> 26762.988 | AJ4: =+Tabla_master_rend[[#This Row],[Litros_Leche_Total]]/Tabla_master_rend[[#This Row],[Kg_Queso_Blan]] -> 8.5682136 | AK4: =+Tabla_master_rend[[#This Row],[Litros_Leche_Total]]/(Tabla_master_rend[[#This Row],[Kg_Queso_Blan]]-Tabla_master_rend[[#This Row],[Merma_TOT]]) -> 8.8494834 | AL4: =VLOOKUP(G4,REND_TARGET[#All],8,FALSE) -> 8.494317 | AM4: =(I4*1.03*Tabla_master_rend[[#This Row],[%MG_Leche]])+(I4*1.03*Tabla_master_rend[[#This Row],[%MP_Leche]]) -> 17501.703 | AN4: 0.2846 | AO4: 0.2323 | AP4: 0.5668 | AQ4: =+Tabla_master_rend[[#This Row],[Kg_Queso_Blan]]*Tabla_master_rend[[#This Row],[ES_QUESO]]/(Tabla_master_rend[[#This Row],[Kg_Solidos_leche]]) -> 0.86673059 | AR4: =R4*0.4 -> 1516.68 | AS4: =+(Tabla_master_rend[[#This Row],[Kg_Queso_Blan]]*Tabla_master_rend[[#This Row],[%MG_QUESO]]+(Tabla_master_rend[[#This Row],[Kg_MG_Nata]]))/(Tabla_master_rend[[#This Row],[Litros_Leche_Total]]*1.03*Tabla_master_rend[[#This Row],[%MG_Leche]]) -> 0.96193466 | AT4: =+Tabla_master_rend[[#This Row],[Kg_Queso_Blan]]*Tabla_master_rend[[#This Row],[%PT_QUESO]]/(Tabla_master_rend[[#This Row],[Litros_Leche_Total]]*1.03*Tabla_master_rend[[#This Row],[%MP_Leche]]) -> 0.77646522 | AU4: =AR4*$CO$3 -> 11375.1 | AV4: 64.088406 | AW4: 99.9 | AX4: 6 | AY4: =SUM(Tabla_master_rend[[#This Row],[Kg_Finos]:[Kg_Desmoldeo]]) -> 169.98841 | AZ4: =+(Tabla_master_rend[[#This Row],[Kg_Finos]]+Tabla_master_rend[[#This Row],[Kg_Llenadora]]+Tabla_master_rend[[#This Row],[Kg_Desmoldeo]])/(Tabla_master_rend[[#This Row],[Kg_Queso_Blan]]) -> 0.0063516228 | BA4: 545 | BB4: =+Tabla_master_rend[[#This Row],[L_Agua]]/(Tabla_master_rend[[#This Row],[L_Agua]]+Tabla_master_rend[[#This Row],[Kg_SalidaSecadero]]) -> 0.020494115 | BC4: 3812 | BD4: 3773 | BE4: 26343 | BF4: 0 | BG4: 0 | BH4: =10*6.7 -> 67 | BI4: =14*6.7 -> 93.8 | BJ4: 90 | BK4: 26048 | BL4: 5 | BM4: 116.46 | BN4: 14.18 | BO4: =+SUM(Tabla_master_rend[[#This Row],[B_altas]:[B_lab]])/Tabla_master_rend[[#This Row],[Kg_SalidaSecadero]] -> 0.0096283784 | BP4: =+(Tabla_master_rend[[#This Row],[Kg_mer_env_real]]+Tabla_master_rend[[#This Row],[kg_mer_lab_real]])/Tabla_master_rend[[#This Row],[Kg_SalidaSecadero]] -> 0.0050153563 | BQ4: =+Tabla_master_rend[[#This Row],[Merma_TOT]]/Tabla_master_rend[[#This Row],[Kg_Queso_Blan]] -> 0.03178376 | BR4: =+Tabla_master_rend[[#This Row],[kg_mer_lab_real]]+Tabla_master_rend[[#This Row],[Kg_mer_env_real]]+Tabla_master_rend[[#This Row],[Kg_rebaba]]+Tabla_master_rend[[#This Row],[L_Agua]]+Tabla_master_rend[[#This Row],[Kg_Desmoldeo]]+Tabla_master_rend[[#This Row],[Kg_Llenadora]]+Tabla_master_rend[[#This Row],[Kg_Finos]] -> 850.62841 | BT4: =IF(+Tabla_master_rend[[#This Row],[Kg_Env_Total]]=0,0,Tabla_master_rend[[#This Row],[Kg_Env_Total]]-Tabla_master_rend[[#This Row],[Kg_SalidaSecadero]]) -> 0 | BU4: =+Tabla_master_rend[[#This Row],[Diferencia_Env_vs_Sec_kg]]/Tabla_master_rend[[#This Row],[Kg_SalidaSecadero]] -> 0 | BV4: =IFERROR(Tabla_master_rend[[#This Row],[Litros_Leche_Total]]*SUMIFS(tbl_PrecioLeche[PMV_eur_L],tbl_PrecioLeche[AñoMes],TEXT(Tabla_master_rend[[#This Row],[Fecha]],"yyyy-mm"),tbl_PrecioLeche[Tipo_Leche],Tabla_master_rend[[#This Row],[Tipo_Leche]]),"") -> 0 | BW4: =+(Tabla_master_rend[[#This Row],[Coste_Leche_€]]-Tabla_master_rend[[#This Row],[Kg_MG_Nata]]*$CO$3)/Tabla_master_rend[[#This Row],[Kg_Queso_Blan]] -> -0.42503101 | BX4: =SUM(Tabla_master_rend[[#This Row],[Kg_Finos]:[Kg_Desmoldeo]])+Tabla_master_rend[[#This Row],[L_Agua]]+SUM(Tabla_master_rend[[#This Row],[B_altas]:[B_lab]]) -> 965.78841 | BY4: =+BX4-Tabla_master_rend[[#This Row],[Merma_TOT]] -> 115.16 | BZ4: =+BY4/BX4 -> 0.11923937 | CA4: =+Tabla_master_rend[[#This Row],[Kg_Queso_Blan]]*$CA$1 -> 173.95942 | CB4: =+Tabla_master_rend[[#This Row],[Kg_Queso_Blan]]*($CB$1-$CA$1) -> 93.670459 | CC4: =+(Tabla_master_rend[[#This Row],[Kg_Queso_Blan]]-CA4-CB4)*$CC$1 -> 278.20126 | CD4: =+CA4+CB4+CC4 -> 545.83115 | CE4: =+CD4/Tabla_master_rend[[#This Row],[Kg_Queso_Blan]] -> 0.020395 | CF4: =+Tabla_master_rend[[#This Row],[Merma_TOT]]/Tabla_master_rend[[#This Row],[Kg_Queso_Blan]] -> 0.03178376 | CG4: =CD4-Tabla_master_rend[[#This Row],[Merma_TOT]] -> -304.79726 | CH4: {=-BR4 * IFERROR(INDEX('Precio Leche_EBITDA_Ventas'!$BD$87:$BD$110,MATCH(1,('Precio Leche_EBITDA_Ventas'!$AZ$87:$AZ$110=YEAR(A4))*('Precio Leche_EBITDA_Ventas'!$BB$87:$BB$110=C4),0)),1.3)} -> -2977.1994 | CI4: =+CG4*$CM$2 -> -396.23643 | CK4: Venta kg Merma | CM4: 3.475
A5: 45664 | B5: 1 | C5: =+UPPER(TEXT(Tabla_master_rend[[#This Row],[Fecha]],"MMM")) -> ENE | D5: =+UPPER(TEXT(Tabla_master_rend[[#This Row],[Fecha]],"ddd")) -> MA | E5: 070125216 | F5: VACA | G5: EDAM | H5: 17 | I5: =+Tabla_master_rend[[#This Row],[L_Leche_ent]]+Tabla_master_rend[[#This Row],[L_desn_ext]]+Tabla_master_rend[[#This Row],[L_cabra]]+Tabla_master_rend[[#This Row],[L_oveja]] -> 254077 | J5: 254077 | K5: 0.0391 | L5: 0.0338 | M5: =0.93*K5+0.74*L5+0.048 -> 0.109375 | N5: NO | O5: 0 | P5: 0 | Q5: 0 | R5: 7660 | T5: 235530 | U5: =+Tabla_master_rend[[#This Row],[L_suero Total]]/Tabla_master_rend[[#This Row],[Litros_Leche_Total]] -> 0.92700244 | V5: 0.0017 | W5: 0.01 | X5: 152821 | Y5: 49494 | Z5: =IF(Tabla_master_rend[[#This Row],[L_suero para con]]=0,0,+Tabla_master_rend[[#This Row],[L_suero para con]]/Tabla_master_rend[[#This Row],[L_suero_con]]) -> 3.0876672 | AA5: =+Tabla_master_rend[[#This Row],[L_suero Total]]-Tabla_master_rend[[#This Row],[L_suero para con]] -> 82709 | AD5: 0 | AE5: 0 | AF5: 0 | AG5: 0 | AH5: 0 | AI5: =+Tabla_master_rend[[#This Row],[Kg_Finos]]+Tabla_master_rend[[#This Row],[Kg_Llenadora]]+Tabla_master_rend[[#This Row],[Kg_Desmoldeo]]+Tabla_master_rend[[#This Row],[L_Agua]]+Tabla_master_rend[[#This Row],[Kg_SalidaSecadero]] -> 29718.7 | AJ5: =+Tabla_master_rend[[#This Row],[Litros_Leche_Total]]/Tabla_master_rend[[#This Row],[Kg_Queso_Blan]] -> 8.5493982 | AK5: =+Tabla_master_rend[[#This Row],[Litros_Leche_Total]]/(Tabla_master_rend[[#This Row],[Kg_Queso_Blan]]-Tabla_master_rend[[#This Row],[Merma_TOT]]) -> 9.0595862 | AL5: =VLOOKUP(G5,REND_TARGET[#All],8,FALSE) -> 9.195758 | AM5: =(I5*1.03*Tabla_master_rend[[#This Row],[%MG_Leche]])+(I5*1.03*Tabla_master_rend[[#This Row],[%MP_Leche]]) -> 19077.88 | AN5: 0.2329 | AO5: 0.2339 | AP5: 0.5199 | AQ5: =+Tabla_master_rend[[#This Row],[Kg_Queso_Blan]]*Tabla_master_rend[[#This Row],[ES_QUESO]]/(Tabla_master_rend[[#This Row],[Kg_Solidos_leche]]) -> 0.80987785 | AR5: =R5*0.4 -> 3064 | AS5: =+(Tabla_master_rend[[#This Row],[Kg_Queso_Blan]]*Tabla_master_rend[[#This Row],[%MG_QUESO]]+(Tabla_master_rend[[#This Row],[Kg_MG_Nata]]))/(Tabla_master_rend[[#This Row],[Litros_Leche_Total]]*1.03*Tabla_master_rend[[#This Row],[%MG_Leche]]) -> 0.97586522 | AT5: =+Tabla_master_rend[[#This Row],[Kg_Queso_Blan]]*Tabla_master_rend[[#This Row],[%PT_QUESO]]/(Tabla_master_rend[[#This Row],[Litros_Leche_Total]]*1.03*Tabla_master_rend[[#This Row],[%MP_Leche]]) -> 0.78585198 | AU5: =AR5*$CO$3 -> 22980 | AV5: 76.7 | AW5: 218 | AX5: 52 | AY5: =SUM(Tabla_master_rend[[#This Row],[Kg_Finos]:[Kg_Desmoldeo]]) -> 346.7 | AZ5: =+(Tabla_master_rend[[#This Row],[Kg_Finos]]+Tabla_master_rend[[#This Row],[Kg_Llenadora]]+Tabla_master_rend[[#This Row],[Kg_Desmoldeo]])/(Tabla_master_rend[[#This Row],[Kg_Queso_Blan]]) -> 0.011666055 | BA5: 570 | BB5: =+Tabla_master_rend[[#This Row],[L_Agua]]/(Tabla_master_rend[[#This Row],[L_Agua]]+Tabla_master_rend[[#This Row],[Kg_SalidaSecadero]]) -> 0.019406237 | BC5: 3994 | BD5: 3806 | BE5: 28079 | BF5: 0 | BG5: 0 | BH5: =6*6.9 -> 41.4 | BI5: =165*6.9 -> 1138.5 | BJ5: 111 | BK5: 28802 | BL5: 1.36 | BM5: 725.88 | BN5: 29.66 | BO5: =+SUM(Tabla_master_rend[[#This Row],[B_altas]:[B_lab]])/Tabla_master_rend[[#This Row],[Kg_SalidaSecadero]] -> 0.044819804 | BP5: =+(Tabla_master_rend[[#This Row],[Kg_mer_env_real]]+Tabla_master_rend[[#This Row],[kg_mer_lab_real]])/Tabla_master_rend[[#This Row],[Kg_SalidaSecadero]] -> 0.026232206 | BQ5: =+Tabla_master_rend[[#This Row],[Merma_TOT]]/Tabla_master_rend[[#This Row],[Kg_Queso_Blan]] -> 0.056314711 | BR5: =+Tabla_master_rend[[#This Row],[kg_mer_lab_real]]+Tabla_master_rend[[#This Row],[Kg_mer_env_real]]+Tabla_master_rend[[#This Row],[Kg_rebaba]]+Tabla_master_rend[[#This Row],[L_Agua]]+Tabla_master_rend[[#This Row],[Kg_Desmoldeo]]+Tabla_master_rend[[#This Row],[Kg_Llenadora]]+Tabla_master_rend[[#This Row],[Kg_Finos]] -> 1673.6 | BT5: =IF(+Tabla_master_rend[[#This Row],[Kg_Env_Total]]=0,0,Tabla_master_rend[[#This Row],[Kg_Env_Total]]-Tabla_master_rend[[#This Row],[Kg_SalidaSecadero]]) -> 0 | BU5: =+Tabla_master_rend[[#This Row],[Diferencia_Env_vs_Sec_kg]]/Tabla_master_rend[[#This Row],[Kg_SalidaSecadero]] -> 0 | BV5: =IFERROR(Tabla_master_rend[[#This Row],[Litros_Leche_Total]]*SUMIFS(tbl_PrecioLeche[PMV_eur_L],tbl_PrecioLeche[AñoMes],TEXT(Tabla_master_rend[[#This Row],[Fecha]],"yyyy-mm"),tbl_PrecioLeche[Tipo_Leche],Tabla_master_rend[[#This Row],[Tipo_Leche]]),"") -> 0 | BW5: =+(Tabla_master_rend[[#This Row],[Coste_Leche_€]]-Tabla_master_rend[[#This Row],[Kg_MG_Nata]]*$CO$3)/Tabla_master_rend[[#This Row],[Kg_Queso_Blan]] -> -0.77325051 | BX5: =SUM(Tabla_master_rend[[#This Row],[Kg_Finos]:[Kg_Desmoldeo]])+Tabla_master_rend[[#This Row],[L_Agua]]+SUM(Tabla_master_rend[[#This Row],[B_altas]:[B_lab]]) -> 2207.6 | BY5: =+BX5-Tabla_master_rend[[#This Row],[Merma_TOT]] -> 534 | BZ5: =+BY5/BX5 -> 0.24189165 | CA5: =+Tabla_master_rend[[#This Row],[Kg_Queso_Blan]]*$CA$1 -> 193.17155 | CB5: =+Tabla_master_rend[[#This Row],[Kg_Queso_Blan]]*($CB$1-$CA$1) -> 104.01545 | CC5: =+(Tabla_master_rend[[#This Row],[Kg_Queso_Blan]]-CA5-CB5)*$CC$1 -> 308.92589 | CD5: =+CA5+CB5+CC5 -> 606.11289 | CE5: =+CD5/Tabla_master_rend[[#This Row],[Kg_Queso_Blan]] -> 0.020395 | CF5: =+Tabla_master_rend[[#This Row],[Merma_TOT]]/Tabla_master_rend[[#This Row],[Kg_Queso_Blan]] -> 0.056314711 | CG5: =CD5-Tabla_master_rend[[#This Row],[Merma_TOT]] -> -1067.4871 | CH5: {=-BR5 * IFERROR(INDEX('Precio Leche_EBITDA_Ventas'!$BD$87:$BD$110,MATCH(1,('Precio Leche_EBITDA_Ventas'!$AZ$87:$AZ$110=YEAR(A5))*('Precio Leche_EBITDA_Ventas'!$BB$87:$BB$110=C5),0)),1.3)} -> -5857.6 | CI5: =+CG5*$CM$2 -> -1387.7332
A6: 45665 | B6: 1 | C6: =+UPPER(TEXT(Tabla_master_rend[[#This Row],[Fecha]],"MMM")) -> ENE | D6: =+UPPER(TEXT(Tabla_master_rend[[#This Row],[Fecha]],"ddd")) -> MI | E6: 080125216 | F6: VACA | G6: EDAM | H6: 15 | I6: =+Tabla_master_rend[[#This Row],[L_Leche_ent]]+Tabla_master_rend[[#This Row],[L_desn_ext]]+Tabla_master_rend[[#This Row],[L_cabra]]+Tabla_master_rend[[#This Row],[L_oveja]] -> 224034 | J6: 224034 | K6: 0.0386 | L6: 0.0338 | M6: =0.93*K6+0.74*L6+0.048 -> 0.10891 | N6: NO | O6: 0 | P6: 0 | Q6: 0 | R6: 6660 | T6: 208090 | U6: =+Tabla_master_rend[[#This Row],[L_suero Total]]/Tabla_master_rend[[#This Row],[Litros_Leche_Total]] -> 0.92883223 | V6: 0.0017 | W6: 0.0101 | X6: 160816 | Y6: 49678 | Z6: =IF(Tabla_master_rend[[#This Row],[L_suero para con]]=0,0,+Tabla_master_rend[[#This Row],[L_suero para con]]/Tabla_master_rend[[#This Row],[L_suero_con]]) -> 3.2371674 | AA6: =+Tabla_master_rend[[#This Row],[L_suero Total]]-Tabla_master_rend[[#This Row],[L_suero para con]] -> 47274 | AD6: 8862 | AE6: 0 | AF6: 0 | AI6: =+Tabla_master_rend[[#This Row],[Kg_Finos]]+Tabla_master_rend[[#This Row],[Kg_Llenadora]]+Tabla_master_rend[[#This Row],[Kg_Desmoldeo]]+Tabla_master_rend[[#This Row],[L_Agua]]+Tabla_master_rend[[#This Row],[Kg_SalidaSecadero]] -> 25124.08 | AJ6: =+Tabla_master_rend[[#This Row],[Litros_Leche_Total]]/Tabla_master_rend[[#This Row],[Kg_Queso_Blan]] -> 8.9171026 | AK6: =+Tabla_master_rend[[#This Row],[Litros_Leche_Total]]/(Tabla_master_rend[[#This Row],[Kg_Queso_Blan]]-Tabla_master_rend[[#This Row],[Merma_TOT]]) -> 9.5233844 | AL6: =VLOOKUP(G6,REND_TARGET[#All],8,FALSE) -> 9.195758 | AM6: =(I6*1.03*Tabla_master_rend[[#This Row],[%MG_Leche]])+(I6*1.03*Tabla_master_rend[[#This Row],[%MP_Leche]]) -> 16706.663 | AN6: 0.2404 | AO6: 0.2387 | AP6: 0.5299 | AQ6: =+Tabla_master_rend[[#This Row],[Kg_Queso_Blan]]*Tabla_master_rend[[#This Row],[ES_QUESO]]/(Tabla_master_rend[[#This Row],[Kg_Solidos_leche]]) -> 0.79688264 | AR6: =R6*0.4 -> 2664 | AS6: =+(Tabla_master_rend[[#This Row],[Kg_Queso_Blan]]*Tabla_master_rend[[#This Row],[%MG_QUESO]]+(Tabla_master_rend[[#This Row],[Kg_MG_Nata]]))/(Tabla_master_rend[[#This Row],[Litros_Leche_Total]]*1.03*Tabla_master_rend[[#This Row],[%MG_Leche]]) -> 0.97717395 | AT6: =+Tabla_master_rend[[#This Row],[Kg_Queso_Blan]]*Tabla_master_rend[[#This Row],[%PT_QUESO]]/(Tabla_master_rend[[#This Row],[Litros_Leche_Total]]*1.03*Tabla_master_rend[[#This Row],[%MP_Leche]]) -> 0.76890862 | AU6: =AR6*$CO$3 -> 19980 | AV6: 46.58 | AW6: 155 | AX6: 102.5 | AY6: =SUM(Tabla_master_rend[[#This Row],[Kg_Finos]:[Kg_Desmoldeo]]) -> 304.08 | AZ6: =+(Tabla_master_rend[[#This Row],[Kg_Finos]]+Tabla_master_rend[[#This Row],[Kg_Llenadora]]+Tabla_master_rend[[#This Row],[Kg_Desmoldeo]])/(Tabla_master_rend[[#This Row],[Kg_Queso_Blan]]) -> 0.01210313 | BA6: 520 | BB6: =+Tabla_master_rend[[#This Row],[L_Agua]]/(Tabla_master_rend[[#This Row],[L_Agua]]+Tabla_master_rend[[#This Row],[Kg_SalidaSecadero]]) -> 0.020950846 | BC6: 3417 | BD6: 3203 | BE6: 23386 | BF6: 0 | BG6: 0 | BH6: =16*6.7 -> 107.2 | BI6: =177*6.7 -> 1185.9 | BJ6: 96 | BK6: 24300 | BL6: 1.26 | BM6: 753.62 | BN6: 20.5 | BO6: =+SUM(Tabla_master_rend[[#This Row],[B_altas]:[B_lab]])/Tabla_master_rend[[#This Row],[Kg_SalidaSecadero]] -> 0.057164609 | BP6: =+(Tabla_master_rend[[#This Row],[Kg_mer_env_real]]+Tabla_master_rend[[#This Row],[kg_mer_lab_real]])/Tabla_master_rend[[#This Row],[Kg_SalidaSecadero]] -> 0.03185679 | BQ6: =+Tabla_master_rend[[#This Row],[Merma_TOT]]/Tabla_master_rend[[#This Row],[Kg_Queso_Blan]] -> 0.063662431 | BR6: =+Tabla_master_rend[[#This Row],[kg_mer_lab_real]]+Tabla_master_rend[[#This Row],[Kg_mer_env_real]]+Tabla_master_rend[[#This Row],[Kg_rebaba]]+Tabla_master_rend[[#This Row],[L_Agua]]+Tabla_master_rend[[#This Row],[Kg_Desmoldeo]]+Tabla_master_rend[[#This Row],[Kg_Llenadora]]+Tabla_master_rend[[#This Row],[Kg_Finos]] -> 1599.46 | BT6: =IF(+Tabla_master_rend[[#This Row],[Kg_Env_Total]]=0,0,Tabla_master_rend[[#This Row],[Kg_Env_Total]]-Tabla_master_rend[[#This Row],[Kg_SalidaSecadero]]) -> 0 | BU6: =+Tabla_master_rend[[#This Row],[Diferencia_Env_vs_Sec_kg]]/Tabla_master_rend[[#This Row],[Kg_SalidaSecadero]] -> 0 | BV6: =IFERROR(Tabla_master_rend[[#This Row],[Litros_Leche_Total]]*SUMIFS(tbl_PrecioLeche[PMV_eur_L],tbl_PrecioLeche[AñoMes],TEXT(Tabla_master_rend[[#This Row],[Fecha]],"yyyy-mm"),tbl_PrecioLeche[Tipo_Leche],Tabla_master_rend[[#This Row],[Tipo_Leche]]),"") -> 0 | BW6: =+(Tabla_master_rend[[#This Row],[Coste_Leche_€]]-Tabla_master_rend[[#This Row],[Kg_MG_Nata]]*$CO$3)/Tabla_master_rend[[#This Row],[Kg_Queso_Blan]] -> -0.795253 | BX6: =SUM(Tabla_master_rend[[#This Row],[Kg_Finos]:[Kg_Desmoldeo]])+Tabla_master_rend[[#This Row],[L_Agua]]+SUM(Tabla_master_rend[[#This Row],[B_altas]:[B_lab]]) -> 2213.18 | BY6: =+BX6-Tabla_master_rend[[#This Row],[Merma_TOT]] -> 613.72 | BZ6: =+BY6/BX6 -> 0.27730234 | CA6: =+Tabla_master_rend[[#This Row],[Kg_Queso_Blan]]*$CA$1 -> 163.30652 | CB6: =+Tabla_master_rend[[#This Row],[Kg_Queso_Blan]]*($CB$1-$CA$1) -> 87.93428 | CC6: =+(Tabla_master_rend[[#This Row],[Kg_Queso_Blan]]-CA6-CB6)*$CC$1 -> 261.16481 | CD6: =+CA6+CB6+CC6 -> 512.40561 | CE6: =+CD6/Tabla_master_rend[[#This Row],[Kg_Queso_Blan]] -> 0.020395 | CF6: =+Tabla_master_rend[[#This Row],[Merma_TOT]]/Tabla_master_rend[[#This Row],[Kg_Queso_Blan]] -> 0.063662431 | CG6: =CD6-Tabla_master_rend[[#This Row],[Merma_TOT]] -> -1087.0544 | CH6: {=-BR6 * IFERROR(INDEX('Precio Leche_EBITDA_Ventas'!$BD$87:$BD$110,MATCH(1,('Precio Leche_EBITDA_Ventas'!$AZ$87:$AZ$110=YEAR(A6))*('Precio Leche_EBITDA_Ventas'!$BB$87:$BB$110=C6),0)),1.3)} -> -5598.11 | CI6: =+CG6*$CM$2 -> -1413.1707
A7: 45667 | B7: 1 | C7: =+UPPER(TEXT(Tabla_master_rend[[#This Row],[Fecha]],"MMM")) -> ENE | D7: =+UPPER(TEXT(Tabla_master_rend[[#This Row],[Fecha]],"ddd")) -> VI | E7: 100125326 | F7: VACA | G7: GOUDA_F | H7: 13 | I7: =+Tabla_master_rend[[#This Row],[L_Leche_ent]]+Tabla_master_rend[[#This Row],[L_desn_ext]]+Tabla_master_rend[[#This Row],[L_cabra]]+Tabla_master_rend[[#This Row],[L_oveja]] -> 204429 | J7: 204429 | K7: 0.0388 | L7: 0.0335 | M7: =0.93*K7+0.74*L7+0.048 -> 0.108874 | N7: SI | O7: 0 | P7: 0 | Q7: 0 | R7: 3045 | T7: 182000 | U7: =+Tabla_master_rend[[#This Row],[L_suero Total]]/Tabla_master_rend[[#This Row],[Litros_Leche_Total]] -> 0.89028465 | V7: 0.0018 | W7: 0.009 | X7: 149545 | Y7: 49146 | Z7: =IF(Tabla_master_rend[[#This Row],[L_suero para con]]=0,0,+Tabla_master_rend[[#This Row],[L_suero para con]]/Tabla_master_rend[[#This Row],[L_suero_con]]) -> 3.0428723 | AA7: =+Tabla_master_rend[[#This Row],[L_suero Total]]-Tabla_master_rend[[#This Row],[L_suero para con]] -> 32455 | AD7: 0 | AE7: 0 | AF7: 0 | AG7: 0 | AH7: 0 | AI7: =+Tabla_master_rend[[#This Row],[Kg_Finos]]+Tabla_master_rend[[#This Row],[Kg_Llenadora]]+Tabla_master_rend[[#This Row],[Kg_Desmoldeo]]+Tabla_master_rend[[#This Row],[L_Agua]]+Tabla_master_rend[[#This Row],[Kg_SalidaSecadero]] -> 22880.11 | AJ7: =+Tabla_master_rend[[#This Row],[Litros_Leche_Total]]/Tabla_master_rend[[#This Row],[Kg_Queso_Blan]] -> 8.934791 | AK7: =+Tabla_master_rend[[#This Row],[Litros_Leche_Total]]/(Tabla_master_rend[[#This Row],[Kg_Queso_Blan]]-Tabla_master_rend[[#This Row],[Merma_TOT]]) -> 9.3994061 | AL7: =VLOOKUP(G7,REND_TARGET[#All],8,FALSE) -> 9.354943 | AM7: =(I7*1.03*Tabla_master_rend[[#This Row],[%MG_Leche]])+(I7*1.03*Tabla_master_rend[[#This Row],[%MP_Leche]]) -> 15223.623 | AN7: 0.2915 | AO7: 0.2383 | AP7: 0.5782 | AQ7: =+Tabla_master_rend[[#This Row],[Kg_Queso_Blan]]*Tabla_master_rend[[#This Row],[ES_QUESO]]/(Tabla_master_rend[[#This Row],[Kg_Solidos_leche]]) -> 0.86899678 | AR7: =R7*0.4 -> 1218 | AS7: =+(Tabla_master_rend[[#This Row],[Kg_Queso_Blan]]*Tabla_master_rend[[#This Row],[%MG_QUESO]]+(Tabla_master_rend[[#This Row],[Kg_MG_Nata]]))/(Tabla_master_rend[[#This Row],[Litros_Leche_Total]]*1.03*Tabla_master_rend[[#This Row],[%MG_Leche]]) -> 0.96545222 | AT7: =+Tabla_master_rend[[#This Row],[Kg_Queso_Blan]]*Tabla_master_rend[[#This Row],[%PT_QUESO]]/(Tabla_master_rend[[#This Row],[Litros_Leche_Total]]*1.03*Tabla_master_rend[[#This Row],[%MP_Leche]]) -> 0.77296106 | AU7: =AR7*$CO$3 -> 9135 | AV7: 44.11 | AW7: 85 | AX7: 44 | AY7: =SUM(Tabla_master_rend[[#This Row],[Kg_Finos]:[Kg_Desmoldeo]]) -> 173.11 | AZ7: =+(Tabla_master_rend[[#This Row],[Kg_Finos]]+Tabla_master_rend[[#This Row],[Kg_Llenadora]]+Tabla_master_rend[[#This Row],[Kg_Desmoldeo]])/(Tabla_master_rend[[#This Row],[Kg_Queso_Blan]]) -> 0.0075659601 | BA7: 450 | BB7: =+Tabla_master_rend[[#This Row],[L_Agua]]/(Tabla_master_rend[[#This Row],[L_Agua]]+Tabla_master_rend[[#This Row],[Kg_SalidaSecadero]]) -> 0.019817677 | BC7: 3084 | BD7: 2957 | BE7: 21824 | BF7: 0 | BG7: 0 | BH7: =4*6.9 -> 27.6 | BI7: =112*6.9 -> 772.8 | BJ7: 83 | BK7: 22257 | BL7: 3.89 | BM7: 497.26 | BN7: 6.71 | BO7: =+SUM(Tabla_master_rend[[#This Row],[B_altas]:[B_lab]])/Tabla_master_rend[[#This Row],[Kg_SalidaSecadero]] -> 0.039690884 | BP7: =+(Tabla_master_rend[[#This Row],[Kg_mer_env_real]]+Tabla_master_rend[[#This Row],[kg_mer_lab_real]])/Tabla_master_rend[[#This Row],[Kg_SalidaSecadero]] -> 0.022643213 | BQ7: =+Tabla_master_rend[[#This Row],[Merma_TOT]]/Tabla_master_rend[[#This Row],[Kg_Queso_Blan]] -> 0.049430269 | BR7: =+Tabla_master_rend[[#This Row],[kg_mer_lab_real]]+Tabla_master_rend[[#This Row],[Kg_mer_env_real]]+Tabla_master_rend[[#This Row],[Kg_rebaba]]+Tabla_master_rend[[#This Row],[L_Agua]]+Tabla_master_rend[[#This Row],[Kg_Desmoldeo]]+Tabla_master_rend[[#This Row],[Kg_Llenadora]]+Tabla_master_rend[[#This Row],[Kg_Finos]] -> 1130.97 | BT7: =IF(+Tabla_master_rend[[#This Row],[Kg_Env_Total]]=0,0,Tabla_master_rend[[#This Row],[Kg_Env_Total]]-Tabla_master_rend[[#This Row],[Kg_SalidaSecadero]]) -> 0 | BU7: =+Tabla_master_rend[[#This Row],[Diferencia_Env_vs_Sec_kg]]/Tabla_master_rend[[#This Row],[Kg_SalidaSecadero]] -> 0 | BV7: =IFERROR(Tabla_master_rend[[#This Row],[Litros_Leche_Total]]*SUMIFS(tbl_PrecioLeche[PMV_eur_L],tbl_PrecioLeche[AñoMes],TEXT(Tabla_master_rend[[#This Row],[Fecha]],"yyyy-mm"),tbl_PrecioLeche[Tipo_Leche],Tabla_master_rend[[#This Row],[Tipo_Leche]]),"") -> 0 | BW7: =+(Tabla_master_rend[[#This Row],[Coste_Leche_€]]-Tabla_master_rend[[#This Row],[Kg_MG_Nata]]*$CO$3)/Tabla_master_rend[[#This Row],[Kg_Queso_Blan]] -> -0.39925507 | BX7: =SUM(Tabla_master_rend[[#This Row],[Kg_Finos]:[Kg_Desmoldeo]])+Tabla_master_rend[[#This Row],[L_Agua]]+SUM(Tabla_master_rend[[#This Row],[B_altas]:[B_lab]]) -> 1506.51 | BY7: =+BX7-Tabla_master_rend[[#This Row],[Merma_TOT]] -> 375.54 | BZ7: =+BY7/BX7 -> 0.24927813 | CA7: =+Tabla_master_rend[[#This Row],[Kg_Queso_Blan]]*$CA$1 -> 148.72071 | CB7: =+Tabla_master_rend[[#This Row],[Kg_Queso_Blan]]*($CB$1-$CA$1) -> 80.080385 | CC7: =+(Tabla_master_rend[[#This Row],[Kg_Queso_Blan]]-CA7-CB7)*$CC$1 -> 237.83874 | CD7: =+CA7+CB7+CC7 -> 466.63984 | CE7: =+CD7/Tabla_master_rend[[#This Row],[Kg_Queso_Blan]] -> 0.020395 | CF7: =+Tabla_master_rend[[#This Row],[Merma_TOT]]/Tabla_master_rend[[#This Row],[Kg_Queso_Blan]] -> 0.049430269 | CG7: =CD7-Tabla_master_rend[[#This Row],[Merma_TOT]] -> -664.33016 | CH7: {=-BR7 * IFERROR(INDEX('Precio Leche_EBITDA_Ventas'!$BD$87:$BD$110,MATCH(1,('Precio Leche_EBITDA_Ventas'!$AZ$87:$AZ$110=YEAR(A7))*('Precio Leche_EBITDA_Ventas'!$BB$87:$BB$110=C7),0)),1.3)} -> -3958.395 | CI7: =+CG7*$CM$2 -> -863.6292
A8: 45670 | B8: 1 | C8: =+UPPER(TEXT(Tabla_master_rend[[#This Row],[Fecha]],"MMM")) -> ENE | D8: =+UPPER(TEXT(Tabla_master_rend[[#This Row],[Fecha]],"ddd")) -> LU | E8: 130125316 | F8: VACA | G8: EDAM_F | H8: 16 | I8: =+Tabla_master_rend[[#This Row],[L_Leche_ent]]+Tabla_master_rend[[#This Row],[L_desn_ext]]+Tabla_master_rend[[#This Row],[L_cabra]]+Tabla_master_rend[[#This Row],[L_oveja]] -> 259322 | J8: 259322 | K8: 0.0372 | L8: 0.0334 | M8: =0.93*K8+0.74*L8+0.048 -> 0.107312 | N8: NO | O8: 0 | P8: 0 | Q8: 0 | R8: 7727 | T8: 223450 | U8: =+Tabla_master_rend[[#This Row],[L_suero Total]]/Tabla_master_rend[[#This Row],[Litros_Leche_Total]] -> 0.86167005 | V8: 0.0011 | W8: 0.0091 | X8: 134124 | Y8: 38013 | Z8: =IF(Tabla_master_rend[[#This Row],[L_suero para con]]=0,0,+Tabla_master_rend[[#This Row],[L_suero para con]]/Tabla_master_rend[[#This Row],[L_suero_con]]) -> 3.5283719 | AA8: =+Tabla_master_rend[[#This Row],[L_suero Total]]-Tabla_master_rend[[#This Row],[L_suero para con]] -> 89326 | AD8: 0 | AE8: 0 | AF8: 0 | AG8: 0 | AH8: 0 | AI8: =+Tabla_master_rend[[#This Row],[Kg_Finos]]+Tabla_master_rend[[#This Row],[Kg_Llenadora]]+Tabla_master_rend[[#This Row],[Kg_Desmoldeo]]+Tabla_master_rend[[#This Row],[L_Agua]]+Tabla_master_rend[[#This Row],[Kg_SalidaSecadero]] -> 28427.92 | AJ8: =+Tabla_master_rend[[#This Row],[Litros_Leche_Total]]/Tabla_master_rend[[#This Row],[Kg_Queso_Blan]] -> 9.1220884 | AK8: =+Tabla_master_rend[[#This Row],[Litros_Leche_Total]]/(Tabla_master_rend[[#This Row],[Kg_Queso_Blan]]-Tabla_master_rend[[#This Row],[Merma_TOT]]) -> 10.262488 | AL8: =VLOOKUP(G8,REND_TARGET[#All],8,FALSE) -> 9.80785 | AM8: =(I8*1.03*Tabla_master_rend[[#This Row],[%MG_Leche]])+(I8*1.03*Tabla_master_rend[[#This Row],[%MP_Leche]]) -> 18857.377 | AN8: 0.2365 | AO8: 0.254 | AP8: 0.5423 | AQ8: =+Tabla_master_rend[[#This Row],[Kg_Queso_Blan]]*Tabla_master_rend[[#This Row],[ES_QUESO]]/(Tabla_master_rend[[#This Row],[Kg_Solidos_leche]]) -> 0.81752944 | AR8: =R8*0.4 -> 3090.8 | AS8: =+(Tabla_master_rend[[#This Row],[Kg_Queso_Blan]]*Tabla_master_rend[[#This Row],[%MG_QUESO]]+(Tabla_master_rend[[#This Row],[Kg_MG_Nata]]))/(Tabla_master_rend[[#This Row],[Litros_Leche_Total]]*1.03*Tabla_master_rend[[#This Row],[%MG_Leche]]) -> 0.98770366 | AT8: =+Tabla_master_rend[[#This Row],[Kg_Queso_Blan]]*Tabla_master_rend[[#This Row],[%PT_QUESO]]/(Tabla_master_rend[[#This Row],[Litros_Leche_Total]]*1.03*Tabla_master_rend[[#This Row],[%MP_Leche]]) -> 0.80938611 | AU8: =AR8*$CO$3 -> 23181 | AV8: 52.92 | AW8: 88.4 | AX8: 282.6 | AY8: =SUM(Tabla_master_rend[[#This Row],[Kg_Finos]:[Kg_Desmoldeo]]) -> 423.92 | AZ8: =+(Tabla_master_rend[[#This Row],[Kg_Finos]]+Tabla_master_rend[[#This Row],[Kg_Llenadora]]+Tabla_master_rend[[#This Row],[Kg_Desmoldeo]])/(Tabla_master_rend[[#This Row],[Kg_Queso_Blan]]) -> 0.0149121 | BA8: 575 | BB8: =+Tabla_master_rend[[#This Row],[L_Agua]]/(Tabla_master_rend[[#This Row],[L_Agua]]+Tabla_master_rend[[#This Row],[Kg_SalidaSecadero]]) -> 0.020532781 | BC8: 3973 | BD8: 3367 | BE8: 23363 | BF8: 0 | BG8: 0 | BH8: =4*7.7 -> 30.8 | BI8: =588*7.7 -> 4527.6 | BJ8: 86 | BK8: 27429 | BL8: 4.23 | BM8: 2137.88 | BN8: 17.97 | BO8: =+SUM(Tabla_master_rend[[#This Row],[B_altas]:[B_lab]])/Tabla_master_rend[[#This Row],[Kg_SalidaSecadero]] -> 0.16932444 | BP8: =+(Tabla_master_rend[[#This Row],[Kg_mer_env_real]]+Tabla_master_rend[[#This Row],[kg_mer_lab_real]])/Tabla_master_rend[[#This Row],[Kg_SalidaSecadero]] -> 0.07859747 | BQ8: =+Tabla_master_rend[[#This Row],[Merma_TOT]]/Tabla_master_rend[[#This Row],[Kg_Queso_Blan]] -> 0.11112315 | BR8: =+Tabla_master_rend[[#This Row],[kg_mer_lab_real]]+Tabla_master_rend[[#This Row],[Kg_mer_env_real]]+Tabla_master_rend[[#This Row],[Kg_rebaba]]+Tabla_master_rend[[#This Row],[L_Agua]]+Tabla_master_rend[[#This Row],[Kg_Desmoldeo]]+Tabla_master_rend[[#This Row],[Kg_Llenadora]]+Tabla_master_rend[[#This Row],[Kg_Finos]] -> 3159 | BT8: =IF(+Tabla_master_rend[[#This Row],[Kg_Env_Total]]=0,0,Tabla_master_rend[[#This Row],[Kg_Env_Total]]-Tabla_master_rend[[#This Row],[Kg_SalidaSecadero]]) -> 0 | BU8: =+Tabla_master_rend[[#This Row],[Diferencia_Env_vs_Sec_kg]]/Tabla_master_rend[[#This Row],[Kg_SalidaSecadero]] -> 0 | BV8: =IFERROR(Tabla_master_rend[[#This Row],[Litros_Leche_Total]]*SUMIFS(tbl_PrecioLeche[PMV_eur_L],tbl_PrecioLeche[AñoMes],TEXT(Tabla_master_rend[[#This Row],[Fecha]],"yyyy-mm"),tbl_PrecioLeche[Tipo_Leche],Tabla_master_rend[[#This Row],[Tipo_Leche]]),"") -> 0 | BW8: =+(Tabla_master_rend[[#This Row],[Coste_Leche_€]]-Tabla_master_rend[[#This Row],[Kg_MG_Nata]]*$CO$3)/Tabla_master_rend[[#This Row],[Kg_Queso_Blan]] -> -0.81543075 | BX8: =SUM(Tabla_master_rend[[#This Row],[Kg_Finos]:[Kg_Desmoldeo]])+Tabla_master_rend[[#This Row],[L_Agua]]+SUM(Tabla_master_rend[[#This Row],[B_altas]:[B_lab]]) -> 5643.32 | BY8: =+BX8-Tabla_master_rend[[#This Row],[Merma_TOT]] -> 2484.32 | BZ8: =+BY8/BX8 -> 0.44022313 | CA8: =+Tabla_master_rend[[#This Row],[Kg_Queso_Blan]]*$CA$1 -> 184.78148 | CB8: =+Tabla_master_rend[[#This Row],[Kg_Queso_Blan]]*($CB$1-$CA$1) -> 99.49772 | CC8: =+(Tabla_master_rend[[#This Row],[Kg_Queso_Blan]]-CA8-CB8)*$CC$1 -> 295.50823 | CD8: =+CA8+CB8+CC8 -> 579.78743 | CE8: =+CD8/Tabla_master_rend[[#This Row],[Kg_Queso_Blan]] -> 0.020395 | CF8: =+Tabla_master_rend[[#This Row],[Merma_TOT]]/Tabla_master_rend[[#This Row],[Kg_Queso_Blan]] -> 0.11112315 | CG8: =CD8-Tabla_master_rend[[#This Row],[Merma_TOT]] -> -2579.2126 | CH8: {=-BR8 * IFERROR(INDEX('Precio Leche_EBITDA_Ventas'!$BD$87:$BD$110,MATCH(1,('Precio Leche_EBITDA_Ventas'!$AZ$87:$AZ$110=YEAR(A8))*('Precio Leche_EBITDA_Ventas'!$BB$87:$BB$110=C8),0)),1.3)} -> -11056.5 | CI8: =+CG8*$CM$2 -> -3352.9763
A9: 45673 | B9: 1 | C9: =+UPPER(TEXT(Tabla_master_rend[[#This Row],[Fecha]],"MMM")) -> ENE | D9: =+UPPER(TEXT(Tabla_master_rend[[#This Row],[Fecha]],"ddd")) -> JU | E9: 160125026 | F9: VACA | G9: GOUDA | H9: 17 | I9: =+Tabla_master_rend[[#This Row],[L_Leche_ent]]+Tabla_master_rend[[#This Row],[L_desn_ext]]+Tabla_master_rend[[#This Row],[L_cabra]]+Tabla_master_rend[[#This Row],[L_oveja]] -> 242694 | J9: 242694 | K9: 0.0393 | L9: 0.0345 | M9: =0.93*K9+0.74*L9+0.048 -> 0.110079 | N9: SI | O9: 0 | P9: 0 | Q9: 0 | R9: 2715 | T9: 223400 | U9: =+Tabla_master_rend[[#This Row],[L_suero Total]]/Tabla_master_rend[[#This Row],[Litros_Leche_Total]] -> 0.92050071 | V9: 0.0026 | W9: 0.0101 | X9: 142428 | Y9: 43435 | Z9: =IF(Tabla_master_rend[[#This Row],[L_suero para con]]=0,0,+Tabla_master_rend[[#This Row],[L_suero para con]]/Tabla_master_rend[[#This Row],[L_suero_con]]) -> 3.2791067 | AA9: =+Tabla_master_rend[[#This Row],[L_suero Total]]-Tabla_master_rend[[#This Row],[L_suero para con]] -> 80972 | AD9: 0 | AE9: 0 | AF9: 0 | AG9: 0 | AH9: 0 | AI9: =+Tabla_master_rend[[#This Row],[Kg_Finos]]+Tabla_master_rend[[#This Row],[Kg_Llenadora]]+Tabla_master_rend[[#This Row],[Kg_Desmoldeo]]+Tabla_master_rend[[#This Row],[L_Agua]]+Tabla_master_rend[[#This Row],[Kg_SalidaSecadero]] -> 30210.38 | AJ9: =+Tabla_master_rend[[#This Row],[Litros_Leche_Total]]/Tabla_master_rend[[#This Row],[Kg_Queso_Blan]] -> 8.033464 | AK9: =+Tabla_master_rend[[#This Row],[Litros_Leche_Total]]/(Tabla_master_rend[[#This Row],[Kg_Queso_Blan]]-Tabla_master_rend[[#This Row],[Merma_TOT]]) -> 8.2873143 | AL9: =VLOOKUP(G9,REND_TARGET[#All],8,FALSE) -> 8.494317 | AM9: =(I9*1.03*Tabla_master_rend[[#This Row],[%MG_Leche]])+(I9*1.03*Tabla_master_rend[[#This Row],[%MP_Leche]]) -> 18448.142 | AN9: 0.2854 | AO9: 0.2265 | AP9: 0.5624 | AQ9: =+Tabla_master_rend[[#This Row],[Kg_Queso_Blan]]*Tabla_master_rend[[#This Row],[ES_QUESO]]/(Tabla_master_rend[[#This Row],[Kg_Solidos_leche]]) -> 0.92097719 | AR9: =R9*0.4 -> 1086 | AS9: =+(Tabla_master_rend[[#This Row],[Kg_Queso_Blan]]*Tabla_master_rend[[#This Row],[%MG_QUESO]]+(Tabla_master_rend[[#This Row],[Kg_MG_Nata]]))/(Tabla_master_rend[[#This Row],[Litros_Leche_Total]]*1.03*Tabla_master_rend[[#This Row],[%MG_Leche]]) -> 0.98819545 | AT9: =+Tabla_master_rend[[#This Row],[Kg_Queso_Blan]]*Tabla_master_rend[[#This Row],[%PT_QUESO]]/(Tabla_master_rend[[#This Row],[Litros_Leche_Total]]*1.03*Tabla_master_rend[[#This Row],[%MP_Leche]]) -> 0.79343076 | AU9: =AR9*$CO$3 -> 8145 | AV9: 88.28 | AW9: 133.9 | AX9: 17.2 | AY9: =SUM(Tabla_master_rend[[#This Row],[Kg_Finos]:[Kg_Desmoldeo]]) -> 239.38 | AZ9: =+(Tabla_master_rend[[#This Row],[Kg_Finos]]+Tabla_master_rend[[#This Row],[Kg_Llenadora]]+Tabla_master_rend[[#This Row],[Kg_Desmoldeo]])/(Tabla_master_rend[[#This Row],[Kg_Queso_Blan]]) -> 0.0079237666 | BA9: 580 | BB9: =+Tabla_master_rend[[#This Row],[L_Agua]]/(Tabla_master_rend[[#This Row],[L_Agua]]+Tabla_master_rend[[#This Row],[Kg_SalidaSecadero]]) -> 0.01935204 | BC9: 4022 | BD9: 3996 | BE9: 29803 | BF9: 0 | BG9: 0 | BH9: =2*6.4 -> 12.8 | BI9: =11*6.4 -> 70.4 | BJ9: 85 | BK9: 29391 | BL9: 1.8 | BM9: 82.13 | BN9: 22.07 | BO9: =+SUM(Tabla_master_rend[[#This Row],[B_altas]:[B_lab]])/Tabla_master_rend[[#This Row],[Kg_SalidaSecadero]] -> 0.0057228403 | BP9: =+(Tabla_master_rend[[#This Row],[Kg_mer_env_real]]+Tabla_master_rend[[#This Row],[kg_mer_lab_real]])/Tabla_master_rend[[#This Row],[Kg_SalidaSecadero]] -> 0.003545303 | BQ9: =+Tabla_master_rend[[#This Row],[Merma_TOT]]/Tabla_master_rend[[#This Row],[Kg_Queso_Blan]] -> 0.030631194 | BR9: =+Tabla_master_rend[[#This Row],[kg_mer_lab_real]]+Tabla_master_rend[[#This Row],[Kg_mer_env_real]]+Tabla_master_rend[[#This Row],[Kg_rebaba]]+Tabla_master_rend[[#This Row],[L_Agua]]+Tabla_master_rend[[#This Row],[Kg_Desmoldeo]]+Tabla_master_rend[[#This Row],[Kg_Llenadora]]+Tabla_master_rend[[#This Row],[Kg_Finos]] -> 925.38 | BT9: =IF(+Tabla_master_rend[[#This Row],[Kg_Env_Total]]=0,0,Tabla_master_rend[[#This Row],[Kg_Env_Total]]-Tabla_master_rend[[#This Row],[Kg_SalidaSecadero]]) -> 0 | BU9: =+Tabla_master_rend[[#This Row],[Diferencia_Env_vs_Sec_kg]]/Tabla_master_rend[[#This Row],[Kg_SalidaSecadero]] -> 0 | BV9: =IFERROR(Tabla_master_rend[[#This Row],[Litros_Leche_Total]]*SUMIFS(tbl_PrecioLeche[PMV_eur_L],tbl_PrecioLeche[AñoMes],TEXT(Tabla_master_rend[[#This Row],[Fecha]],"yyyy-mm"),tbl_PrecioLeche[Tipo_Leche],Tabla_master_rend[[#This Row],[Tipo_Leche]]),"") -> 0 | BW9: =+(Tabla_master_rend[[#This Row],[Coste_Leche_€]]-Tabla_master_rend[[#This Row],[Kg_MG_Nata]]*$CO$3)/Tabla_master_rend[[#This Row],[Kg_Queso_Blan]] -> -0.26960932 | BX9: =SUM(Tabla_master_rend[[#This Row],[Kg_Finos]:[Kg_Desmoldeo]])+Tabla_master_rend[[#This Row],[L_Agua]]+SUM(Tabla_master_rend[[#This Row],[B_altas]:[B_lab]]) -> 987.58 | BY9: =+BX9-Tabla_master_rend[[#This Row],[Merma_TOT]] -> 62.2 | BZ9: =+BY9/BX9 -> 0.062982239 | CA9: =+Tabla_master_rend[[#This Row],[Kg_Queso_Blan]]*$CA$1 -> 196.36747 | CB9: =+Tabla_master_rend[[#This Row],[Kg_Queso_Blan]]*($CB$1-$CA$1) -> 105.73633 | CC9: =+(Tabla_master_rend[[#This Row],[Kg_Queso_Blan]]-CA9-CB9)*$CC$1 -> 314.0369 | CD9: =+CA9+CB9+CC9 -> 616.1407 | CE9: =+CD9/Tabla_master_rend[[#This Row],[Kg_Queso_Blan]] -> 0.020395 | CF9: =+Tabla_master_rend[[#This Row],[Merma_TOT]]/Tabla_master_rend[[#This Row],[Kg_Queso_Blan]] -> 0.030631194 | CG9: =CD9-Tabla_master_rend[[#This Row],[Merma_TOT]] -> -309.2393 | CH9: {=-BR9 * IFERROR(INDEX('Precio Leche_EBITDA_Ventas'!$BD$87:$BD$110,MATCH(1,('Precio Leche_EBITDA_Ventas'!$AZ$87:$AZ$110=YEAR(A9))*('Precio Leche_EBITDA_Ventas'!$BB$87:$BB$110=C9),0)),1.3)} -> -3238.83 | CI9: =+CG9*$CM$2 -> -402.01109
A10: 45677 | B10: 1 | C10: =+UPPER(TEXT(Tabla_master_rend[[#This Row],[Fecha]],"MMM")) -> ENE | D10: =+UPPER(TEXT(Tabla_master_rend[[#This Row],[Fecha]],"ddd")) -> LU | E10: 200125016 | F10: VACA | G10: EDAM | H10: 3 | I10: =+Tabla_master_rend[[#This Row],[L_Leche_ent]]+Tabla_master_rend[[#This Row],[L_desn_ext]]+Tabla_master_rend[[#This Row],[L_cabra]]+Tabla_master_rend[[#This Row],[L_oveja]] -> 43234 | J10: 43234 | K10: 0.0383 | L10: 0.0343 | M10: =0.93*K10+0.74*L10+0.048 -> 0.109001 | N10: NO | O10: 0 | P10: 0 | Q10: 0 | R10: 1103 | T10: 43300 | U10: =+Tabla_master_rend[[#This Row],[L_suero Total]]/Tabla_master_rend[[#This Row],[Litros_Leche_Total]] -> 1.0015266 | V10: 0.002 | W10: 0.0107 | X10: 40841 | Y10: 11435 | Z10: =IF(Tabla_master_rend[[#This Row],[L_suero para con]]=0,0,+Tabla_master_rend[[#This Row],[L_suero para con]]/Tabla_master_rend[[#This Row],[L_suero_con]]) -> 3.5715785 | AA10: =+Tabla_master_rend[[#This Row],[L_suero Total]]-Tabla_master_rend[[#This Row],[L_suero para con]] -> 2459 | AD10: 8210 | AE10: 0 | AF10: 0 | AI10: =+Tabla_master_rend[[#This Row],[Kg_Finos]]+Tabla_master_rend[[#This Row],[Kg_Llenadora]]+Tabla_master_rend[[#This Row],[Kg_Desmoldeo]]+Tabla_master_rend[[#This Row],[L_Agua]]+Tabla_master_rend[[#This Row],[Kg_SalidaSecadero]] -> 4858.46 | AJ10: =+Tabla_master_rend[[#This Row],[Litros_Leche_Total]]/Tabla_master_rend[[#This Row],[Kg_Queso_Blan]] -> 8.8987045 | AK10: =+Tabla_master_rend[[#This Row],[Litros_Leche_Total]]/(Tabla_master_rend[[#This Row],[Kg_Queso_Blan]]-Tabla_master_rend[[#This Row],[Merma_TOT]]) -> 9.4562968 | AL10: =VLOOKUP(G10,REND_TARGET[#All],8,FALSE) -> 9.195758 | AM10: =(I10*1.03*Tabla_master_rend[[#This Row],[%MG_Leche]])+(I10*1.03*Tabla_master_rend[[#This Row],[%MP_Leche]]) -> 3232.9521 | AN10: 0.2356 | AO10: 0.2388 | AP10: 0.528 | AQ10: =+Tabla_master_rend[[#This Row],[Kg_Queso_Blan]]*Tabla_master_rend[[#This Row],[ES_QUESO]]/(Tabla_master_rend[[#This Row],[Kg_Solidos_leche]]) -> 0.79347508 | AR10: =R10*0.4 -> 441.2 | AS10: =+(Tabla_master_rend[[#This Row],[Kg_Queso_Blan]]*Tabla_master_rend[[#This Row],[%MG_QUESO]]+(Tabla_master_rend[[#This Row],[Kg_MG_Nata]]))/(Tabla_master_rend[[#This Row],[Litros_Leche_Total]]*1.03*Tabla_master_rend[[#This Row],[%MG_Leche]]) -> 0.92982573 | AT10: =+Tabla_master_rend[[#This Row],[Kg_Queso_Blan]]*Tabla_master_rend[[#This Row],[%PT_QUESO]]/(Tabla_master_rend[[#This Row],[Litros_Leche_Total]]*1.03*Tabla_master_rend[[#This Row],[%MP_Leche]]) -> 0.75958467 | AU10: =AR10*$CO$3 -> 3309 | AV10: 10.46 | AW10: 55 | AX10: 27 | AY10: =SUM(Tabla_master_rend[[#This Row],[Kg_Finos]:[Kg_Desmoldeo]]) -> 92.46 | AZ10: =+(Tabla_master_rend[[#This Row],[Kg_Finos]]+Tabla_master_rend[[#This Row],[Kg_Llenadora]]+Tabla_master_rend[[#This Row],[Kg_Desmoldeo]])/(Tabla_master_rend[[#This Row],[Kg_Queso_Blan]]) -> 0.019030722 | BA10: 100 | BB10: =+Tabla_master_rend[[#This Row],[L_Agua]]/(Tabla_master_rend[[#This Row],[L_Agua]]+Tabla_master_rend[[#This Row],[Kg_SalidaSecadero]]) -> 0.020981956 | BC10: 644 | BD10: 610 | BE10: 4548 | BF10: 0 | BG10: =13*6.5 -> 84.5 | BH10: =15*6.5 -> 97.5 | BI10: 0 | BJ10: 37 | BK10: 4666 | BL10: 0 | BM10: 87.71 | BN10: 6.31 | BO10: =+SUM(Tabla_master_rend[[#This Row],[B_altas]:[B_lab]])/Tabla_master_rend[[#This Row],[Kg_SalidaSecadero]] -> 0.046935276 | BP10: =+(Tabla_master_rend[[#This Row],[Kg_mer_env_real]]+Tabla_master_rend[[#This Row],[kg_mer_lab_real]])/Tabla_master_rend[[#This Row],[Kg_SalidaSecadero]] -> 0.020150021 | BQ10: =+Tabla_master_rend[[#This Row],[Merma_TOT]]/Tabla_master_rend[[#This Row],[Kg_Queso_Blan]] -> 0.058965186 | BR10: =+Tabla_master_rend[[#This Row],[kg_mer_lab_real]]+Tabla_master_rend[[#This Row],[Kg_mer_env_real]]+Tabla_master_rend[[#This Row],[Kg_rebaba]]+Tabla_master_rend[[#This Row],[L_Agua]]+Tabla_master_rend[[#This Row],[Kg_Desmoldeo]]+Tabla_master_rend[[#This Row],[Kg_Llenadora]]+Tabla_master_rend[[#This Row],[Kg_Finos]] -> 286.48 | BT10: =IF(+Tabla_master_rend[[#This Row],[Kg_Env_Total]]=0,0,Tabla_master_rend[[#This Row],[Kg_Env_Total]]-Tabla_master_rend[[#This Row],[Kg_SalidaSecadero]]) -> 0 | BU10: =+Tabla_master_rend[[#This Row],[Diferencia_Env_vs_Sec_kg]]/Tabla_master_rend[[#This Row],[Kg_SalidaSecadero]] -> 0 | BV10: =IFERROR(Tabla_master_rend[[#This Row],[Litros_Leche_Total]]*SUMIFS(tbl_PrecioLeche[PMV_eur_L],tbl_PrecioLeche[AñoMes],TEXT(Tabla_master_rend[[#This Row],[Fecha]],"yyyy-mm"),tbl_PrecioLeche[Tipo_Leche],Tabla_master_rend[[#This Row],[Tipo_Leche]]),"") -> 0 | BW10: =+(Tabla_master_rend[[#This Row],[Coste_Leche_€]]-Tabla_master_rend[[#This Row],[Kg_MG_Nata]]*$CO$3)/Tabla_master_rend[[#This Row],[Kg_Queso_Blan]] -> -0.68108001 | BX10: =SUM(Tabla_master_rend[[#This Row],[Kg_Finos]:[Kg_Desmoldeo]])+Tabla_master_rend[[#This Row],[L_Agua]]+SUM(Tabla_master_rend[[#This Row],[B_altas]:[B_lab]]) -> 411.46 | BY10: =+BX10-Tabla_master_rend[[#This Row],[Merma_TOT]] -> 124.98 | BZ10: =+BY10/BX10 -> 0.30374763 | CA10: =+Tabla_master_rend[[#This Row],[Kg_Queso_Blan]]*$CA$1 -> 31.57999 | CB10: =+Tabla_master_rend[[#This Row],[Kg_Queso_Blan]]*($CB$1-$CA$1) -> 17.00461 | CC10: =+(Tabla_master_rend[[#This Row],[Kg_Queso_Blan]]-CA10-CB10)*$CC$1 -> 50.503692 | CD10: =+CA10+CB10+CC10 -> 99.088292 | CE10: =+CD10/Tabla_master_rend[[#This Row],[Kg_Queso_Blan]] -> 0.020395 | CF10: =+Tabla_master_rend[[#This Row],[Merma_TOT]]/Tabla_master_rend[[#This Row],[Kg_Queso_Blan]] -> 0.058965186 | CG10: =CD10-Tabla_master_rend[[#This Row],[Merma_TOT]] -> -187.39171 | CH10: {=-BR10 * IFERROR(INDEX('Precio Leche_EBITDA_Ventas'!$BD$87:$BD$110,MATCH(1,('Precio Leche_EBITDA_Ventas'!$AZ$87:$AZ$110=YEAR(A10))*('Precio Leche_EBITDA_Ventas'!$BB$87:$BB$110=C10),0)),1.3)} -> -1002.68 | CI10: =+CG10*$CM$2 -> -243.60922
A11: 45678 | B11: 1 | C11: =+UPPER(TEXT(Tabla_master_rend[[#This Row],[Fecha]],"MMM")) -> ENE | D11: =+UPPER(TEXT(Tabla_master_rend[[#This Row],[Fecha]],"ddd")) -> MA | E11: 210125026 | F11: VACA | G11: GOUDA | H11: 17 | I11: =+Tabla_master_rend[[#This Row],[L_Leche_ent]]+Tabla_master_rend[[#This Row],[L_desn_ext]]+Tabla_master_rend[[#This Row],[L_cabra]]+Tabla_master_rend[[#This Row],[L_oveja]] -> 243613 | J11: 243613 | K11: 0.038 | L11: 0.0342 | M11: =0.93*K11+0.74*L11+0.048 -> 0.108648 | N11: NO | O11: 0 | P11: 0 | Q11: 0 | R11: 0 | T11: 232070 | U11: =+Tabla_master_rend[[#This Row],[L_suero Total]]/Tabla_master_rend[[#This Row],[Litros_Leche_Total]] -> 0.95261747 | V11: 0.0031 | W11: 0.0101 | X11: 91249 | Y11: 25873 | Z11: =IF(Tabla_master_rend[[#This Row],[L_suero para con]]=0,0,+Tabla_master_rend[[#This Row],[L_suero para con]]/Tabla_master_rend[[#This Row],[L_suero_con]]) -> 3.526804 | AA11: =+Tabla_master_rend[[#This Row],[L_suero Total]]-Tabla_master_rend[[#This Row],[L_suero para con]] -> 140821 | AD11: 42052 | AE11: 0 | AF11: 0 | AI11: =+Tabla_master_rend[[#This Row],[Kg_Finos]]+Tabla_master_rend[[#This Row],[Kg_Llenadora]]+Tabla_master_rend[[#This Row],[Kg_Desmoldeo]]+Tabla_master_rend[[#This Row],[L_Agua]]+Tabla_master_rend[[#This Row],[Kg_SalidaSecadero]] -> 31443.34 | AJ11: =+Tabla_master_rend[[#This Row],[Litros_Leche_Total]]/Tabla_master_rend[[#This Row],[Kg_Queso_Blan]] -> 7.747682 | AK11: =+Tabla_master_rend[[#This Row],[Litros_Leche_Total]]/(Tabla_master_rend[[#This Row],[Kg_Queso_Blan]]-Tabla_master_rend[[#This Row],[Merma_TOT]]) -> 8.0062403 | AL11: =VLOOKUP(G11,REND_TARGET[#All],8,FALSE) -> 8.494317 | AM11: =(I11*1.03*Tabla_master_rend[[#This Row],[%MG_Leche]])+(I11*1.03*Tabla_master_rend[[#This Row],[%MP_Leche]]) -> 18116.524 | AN11: 0.2957 | AO11: 0.2164 | AP11: 0.561 | AQ11: =+Tabla_master_rend[[#This Row],[Kg_Queso_Blan]]*Tabla_master_rend[[#This Row],[ES_QUESO]]/(Tabla_master_rend[[#This Row],[Kg_Solidos_leche]]) -> 0.9736809 | AR11: =R11*0.4 -> 0 | AS11: =+(Tabla_master_rend[[#This Row],[Kg_Queso_Blan]]*Tabla_master_rend[[#This Row],[%MG_QUESO]]+(Tabla_master_rend[[#This Row],[Kg_MG_Nata]]))/(Tabla_master_rend[[#This Row],[Litros_Leche_Total]]*1.03*Tabla_master_rend[[#This Row],[%MG_Leche]]) -> 0.97512146 | AT11: =+Tabla_master_rend[[#This Row],[Kg_Queso_Blan]]*Tabla_master_rend[[#This Row],[%PT_QUESO]]/(Tabla_master_rend[[#This Row],[Litros_Leche_Total]]*1.03*Tabla_master_rend[[#This Row],[%MP_Leche]]) -> 0.79290679 | AU11: =AR11*$CO$3 -> 0 | AV11: 88.24 | AW11: 171.4 | AX11: 34.7 | AY11: =SUM(Tabla_master_rend[[#This Row],[Kg_Finos]:[Kg_Desmoldeo]]) -> 294.34 | AZ11: =+(Tabla_master_rend[[#This Row],[Kg_Finos]]+Tabla_master_rend[[#This Row],[Kg_Llenadora]]+Tabla_master_rend[[#This Row],[Kg_Desmoldeo]])/(Tabla_master_rend[[#This Row],[Kg_Queso_Blan]]) -> 0.0093609648 | BA11: 600 | BB11: =+Tabla_master_rend[[#This Row],[L_Agua]]/(Tabla_master_rend[[#This Row],[L_Agua]]+Tabla_master_rend[[#This Row],[Kg_SalidaSecadero]]) -> 0.019262256 | BC11: 4176 | BD11: 4135 | BE11: 30891 | BF11: =106*6.2 -> 657.2 | BG11: =11*6.2 -> 68.2 | BH11: =9*6.2 -> 55.8 | BI11: =6*6.2 -> 37.2 | BJ11: 96 | BK11: 30549 | BL11: 2.38 | BM11: 102.77 | BN11: 15.96 | BO11: =+SUM(Tabla_master_rend[[#This Row],[B_altas]:[B_lab]])/Tabla_master_rend[[#This Row],[Kg_SalidaSecadero]] -> 0.02993224 | BP11: =+(Tabla_master_rend[[#This Row],[Kg_mer_env_real]]+Tabla_master_rend[[#This Row],[kg_mer_lab_real]])/Tabla_master_rend[[#This Row],[Kg_SalidaSecadero]] -> 0.0038865429 | BQ11: =+Tabla_master_rend[[#This Row],[Merma_TOT]]/Tabla_master_rend[[#This Row],[Kg_Queso_Blan]] -> 0.032294597 | BR11: =+Tabla_master_rend[[#This Row],[kg_mer_lab_real]]+Tabla_master_rend[[#This Row],[Kg_mer_env_real]]+Tabla_master_rend[[#This Row],[Kg_rebaba]]+Tabla_master_rend[[#This Row],[L_Agua]]+Tabla_master_rend[[#This Row],[Kg_Desmoldeo]]+Tabla_master_rend[[#This Row],[Kg_Llenadora]]+Tabla_master_rend[[#This Row],[Kg_Finos]] -> 1015.45 | BT11: =IF(+Tabla_master_rend[[#This Row],[Kg_Env_Total]]=0,0,Tabla_master_rend[[#This Row],[Kg_Env_Total]]-Tabla_master_rend[[#This Row],[Kg_SalidaSecadero]]) -> 0 | BU11: =+Tabla_master_rend[[#This Row],[Diferencia_Env_vs_Sec_kg]]/Tabla_master_rend[[#This Row],[Kg_SalidaSecadero]] -> 0 | BV11: =IFERROR(Tabla_master_rend[[#This Row],[Litros_Leche_Total]]*SUMIFS(tbl_PrecioLeche[PMV_eur_L],tbl_PrecioLeche[AñoMes],TEXT(Tabla_master_rend[[#This Row],[Fecha]],"yyyy-mm"),tbl_PrecioLeche[Tipo_Leche],Tabla_master_rend[[#This Row],[Tipo_Leche]]),"") -> 0 | BW11: =+(Tabla_master_rend[[#This Row],[Coste_Leche_€]]-Tabla_master_rend[[#This Row],[Kg_MG_Nata]]*$CO$3)/Tabla_master_rend[[#This Row],[Kg_Queso_Blan]] -> 0 | BX11: =SUM(Tabla_master_rend[[#This Row],[Kg_Finos]:[Kg_Desmoldeo]])+Tabla_master_rend[[#This Row],[L_Agua]]+SUM(Tabla_master_rend[[#This Row],[B_altas]:[B_lab]]) -> 1808.74 | BY11: =+BX11-Tabla_master_rend[[#This Row],[Merma_TOT]] -> 793.29 | BZ11: =+BY11/BX11 -> 0.43858708 | CA11: =+Tabla_master_rend[[#This Row],[Kg_Queso_Blan]]*$CA$1 -> 204.38171 | CB11: =+Tabla_master_rend[[#This Row],[Kg_Queso_Blan]]*($CB$1-$CA$1) -> 110.05169 | CC11: =+(Tabla_master_rend[[#This Row],[Kg_Queso_Blan]]-CA11-CB11)*$CC$1 -> 326.85352 | CD11: =+CA11+CB11+CC11 -> 641.28692 | CE11: =+CD11/Tabla_master_rend[[#This Row],[Kg_Queso_Blan]] -> 0.020395 | CF11: =+Tabla_master_rend[[#This Row],[Merma_TOT]]/Tabla_master_rend[[#This Row],[Kg_Queso_Blan]] -> 0.032294597 | CG11: =CD11-Tabla_master_rend[[#This Row],[Merma_TOT]] -> -374.16308 | CH11: {=-BR11 * IFERROR(INDEX('Precio Leche_EBITDA_Ventas'!$BD$87:$BD$110,MATCH(1,('Precio Leche_EBITDA_Ventas'!$AZ$87:$AZ$110=YEAR(A11))*('Precio Leche_EBITDA_Ventas'!$BB$87:$BB$110=C11),0)),1.3)} -> -3554.075 | CI11: =+CG11*$CM$2 -> -486.412
